<mujoco model="rehab_v2">
<compiler eulerseq="XYZ" angle="degree"/>
<default>
	<default class="unused"/>
</default>
<asset>
	<texture name="grid" type="2d" builtin="checker" rgb1="0.10000000000000001 0.20000000000000001 0.29999999999999999" rgb2="0.20000000000000001 0.29999999999999999 0.40000000000000002" width="512" height="512"/>
	<material name="grid" class="unused" texture="grid" texrepeat="1 1" texuniform="true" reflectance="0.20000000000000001"/>
	<mesh name="Base" class="unused" file="Base-3252e3830be20ab3491c784a5e5d0a4e10fd3ddf.stl" scale="0.001 0.001 0.001"/>
	<mesh name="Wheel2" class="unused" file="Wheel2-b6704f494d5f9a594781b05c3f016b6cf3e386ee.stl" scale="0.001 0.001 0.001"/>
	<mesh name="Wheel3" class="unused" file="Wheel3-0ced2d4df7eca2372b8cb16c54afc4d1da9d0189.stl" scale="0.001 0.001 0.001"/>
	<mesh name="Wheel1" class="unused" file="Wheel1-45e4e19ad7c5b32903b7f1491fcd6f6887682a78.stl" scale="0.001 0.001 0.001"/>
	<mesh name="Ext_Cover" class="unused" file="Ext_Cover-403156129c1d453c8d66594a926d7ced3f1bca1c.stl" scale="0.001 0.001 0.001"/>
	<mesh name="Extruder" class="unused" file="Extruder-9224e7201b242f71721275aff017d89ba865cc11.stl" scale="0.001 0.001 0.001"/>
	<mesh name="End_Effector" class="unused" file="End_Effector-b5ca03aa368b089816cb85cb5eabaf8c73ff43ab.stl" scale="0.001 0.001 0.001"/>
	<mesh name="Pad" class="unused" file="Pad-dc3a94da00a834e869d6fd3f351d0ceced42a2aa.stl" scale="0.001 0.001 0.001"/>
	<mesh name="Glider" class="unused" file="Glider-1ba75fc49748e3ab2175c7799574a0a1da4f3609.stl" scale="0.001 0.001 0.001"/>
	<mesh name="Ext_Holder" class="unused" file="Ext_Holder-23bfb975c165c895cd1e12b18e387cbad7a0635b.stl" scale="0.001 0.001 0.001"/>
</asset>
<worldbody>
	<geom name="floor" class="unused" type="plane" condim="3" size="0 0 0.050000000000000003" material="grid" pos="0 0 -1"/>
	<body name="Base" pos="0.0010865033095196616 0.19236500102091017 0.31820753236320615" euler="0 -0 0">
		<inertial pos="0 0 0" mass="90.108429138366475" fullinertia="13.440162201021668 9.865328750006217 4.9240148086822453 0.0020396850434465366 0.0021381626864994305 -1.0740804259069854"/>
		<geom name="Base_collision" class="unused" type="mesh" group="3" friction="1 0.0050000000000000001 0.0001" pos="0 0 0" euler="0 -0 0" mesh="Base"/>
		<geom name="Base_visual" class="unused" type="mesh" contype="0" conaffinity="0" group="0" pos="0 0 0" euler="0 -0 0" mesh="Base"/>
		<freejoint name="freejoint"/>
		<body name="Wheel2" pos="0.26851518669091845 0.26395823446350997 -0.24029748697582115" euler="0 -0 0">
			<inertial pos="0 0 0" mass="0.48865434888954207" fullinertia="0.0013756461231507501 0.001012312558013224 0.00083058669792451388 0.00031465314887306023 3.5799104011857709e-09 -5.6327592744764845e-09"/>
			<geom name="Wheel2_collision" class="unused" type="mesh" group="3" friction="1 0.0050000000000000001 0.0001" pos="0 0 0" euler="0 -0 0" mesh="Wheel2"/>
			<geom name="Wheel2_visual" class="unused" type="mesh" contype="0" conaffinity="0" group="0" pos="0 0 0" euler="0 -0 0" mesh="Wheel2"/>
			<joint name="Revolutewheel2" class="unused" type="hinge" pos="-0.0099591777163624551 -0.0057502397722404841 -2.0968384729924683e-06" axis="0.86602540378443982 0.49999999999999795 1.5160278774928361e-12" limited="true" range="0 360"/>
		</body>
		<body name="Wheel3" pos="-0.26604146110209015 0.26337427029853955 -0.24041571260791911" euler="0 -0 0">
			<inertial pos="0 0 0" mass="0.48865394546501528" fullinertia="0.0013756453135292306 0.0010123122124518717 0.00083058578319266871 -0.00031465335420563181 -3.4773366692775199e-09 -6.1939425961554662e-09"/>
			<geom name="Wheel3_collision" class="unused" type="mesh" group="3" friction="1 0.0050000000000000001 0.0001" pos="0 0 0" euler="0 -0 0" mesh="Wheel3"/>
			<geom name="Wheel3_visual" class="unused" type="mesh" contype="0" conaffinity="0" group="0" pos="0 0 0" euler="0 -0 0" mesh="Wheel3"/>
			<joint name="Revolutewheel3" class="unused" type="hinge" pos="0.0099591611142656467 -0.0057501390824674647 -2.1094000868804308e-06" axis="0.86602540378443715 -0.50000000000000266 1.4953161254246909e-12" limited="true" range="0 360"/>
		</body>
		<body name="Wheel1" pos="-0.00052365220291959432 -0.36138585288732694 -0.2402945715772617" euler="0 -0 0">
			<inertial pos="0 0 0" mass="0.48865429991758219" fullinertia="0.00083064868280932559 0.0015573100475043075 0.00083058676337143141 1.626265027676599e-09 -6.8397801959468876e-09 -1.9004840652314671e-10"/>
			<geom name="Wheel1_collision" class="unused" type="mesh" group="3" friction="1 0.0050000000000000001 0.0001" pos="0 0 0" euler="0 -0 0" mesh="Wheel1"/>
			<geom name="Wheel1_visual" class="unused" type="mesh" contype="0" conaffinity="0" group="0" pos="0 0 0" euler="0 -0 0" mesh="Wheel1"/>
			<joint name="Revolutewheel1" class="unused" type="hinge" pos="-2.3174306830551356e-07 0.011500001117956626 -2.099815887085521e-06" axis="7.2514041434689595e-16 -1 3.8951135340141321e-14" limited="true" range="0 360"/>
		</body>
		<body name="Ext_Cover" pos="4.1318191963601088e-05 -0.010681171268652423 0.53612133347818691" euler="0 -0 0">
			<inertial pos="0 0 0" mass="0.34616178772785977" fullinertia="0.011332992188304343 0.00052028550392155921 0.010972517934118093 8.060121878436167e-06 1.7884859627289807e-06 -0.0021409482725401404"/>
			<geom name="Ext_Cover_collision" class="unused" type="mesh" group="3" friction="1 0.0050000000000000001 0.0001" pos="0 0 0" euler="0 -0 0" mesh="Ext_Cover"/>
			<geom name="Ext_Cover_visual" class="unused" type="mesh" contype="0" conaffinity="0" group="0" pos="0 0 0" euler="0 -0 0" mesh="Ext_Cover"/>
			<joint name="Revolute4" class="unused" type="hinge" pos="0.00014602602959263352 -0.29169758357170106 -0.051531387484483826" axis="0.9999997024401851 0.00075700858113645654 0.00014851784230131182" limited="true" range="0 360"/>
			<body name="Extruder" pos="-0.00031124868567762381 0.29145155753928198 0.067426171296196991" euler="0 -0 0">
				<inertial pos="0 0 0" mass="2.022805989913008" fullinertia="0.11012876439131869 0.0044948037000784096 0.10584296200520776 8.1955968061631261e-05 1.5737898077132862e-05 -0.020203233678284232"/>
				<geom name="Extruder_collision" class="unused" type="mesh" group="3" friction="1 0.0050000000000000001 0.0001" pos="0 0 0" euler="0 -0 0" mesh="Extruder"/>
				<geom name="Extruder_visual" class="unused" type="mesh" contype="0" conaffinity="0" group="0" pos="0 0 0" euler="0 -0 0" mesh="Extruder"/>
				<joint name="Slider3" class="unused" type="slide" pos="0.00022872206233827592 -0.29208554231729278 -0.063644723276763071" axis="-0.000771439914313517 0.98129269932287966 0.19252024084774849" limited="true" range="0.01 0.29999999999999999"/>
				<body name="End_Effector" pos="0.033283407675956375 0.29202223840124103 -0.054063341564426048" euler="0 -0 0">
					<inertial pos="0 0 0" mass="1.3416403685863199" fullinertia="0.014082921357678789 0.015567706923254992 0.0029787361109184533 -0.00011048307712142106 0.00055513199897243347 0.0025691518164538138"/>
					<geom name="End_Effector_collision" class="unused" type="mesh" group="3" friction="1 0.0050000000000000001 0.0001" pos="0 0 0" euler="0 -0 0" mesh="End_Effector"/>
					<geom name="End_Effector_visual" class="unused" type="mesh" contype="0" conaffinity="0" group="0" pos="0 0 0" euler="0 -0 0" mesh="End_Effector"/>
					<joint name="Revolute1" class="unused" type="hinge" pos="-0.034997850792678087 -0.020780083818965567 0.10577867589229295" axis="5.3167734707702848e-15 0.19252029813405255 -0.9812929913162407" limited="true" range="-200 25"/>
					<body name="Pad" pos="-0.061519854976631996 0.027589986600880745 -0.13343909545438659" euler="0 -0 0">
						<inertial pos="0 0 0" mass="0.56204913167642356" fullinertia="0.0019913383939866437 0.00065856144511558339 0.0024126944159802862 3.0601883639157282e-05 3.9689518602457953e-06 -0.00037381155819771265"/>
						<geom name="Pad_collision" class="unused" type="mesh" group="3" friction="1 0.0050000000000000001 0.0001" pos="0 0 0" euler="0 -0 0" mesh="Pad"/>
						<geom name="Pad_visual" class="unused" type="mesh" contype="0" conaffinity="0" group="0" pos="0 0 0" euler="0 -0 0" mesh="Pad"/>
						<joint name="Revolute2" class="unused" type="hinge" pos="0.039020566486934541 -0.0024445177902751025 0.0051812491631914037" axis="0.9999997024401851 0.00075700858113640136 0.00014851784230128127" limited="true" range="0 360"/>
					</body>
				</body>
			</body>
		</body>
		<body name="Glider" pos="-0.00021718397414111513 0.21992089725084654 0.54625469774631097" euler="0 -0 0">
			<inertial pos="0 0 0" mass="0.35694878780600747" fullinertia="4.4788011106402336e-05 0.0028736407382672952 0.002857135501313144 -2.1414686182196886e-06 -1.4719591108141473e-06 -3.2988104976539036e-10"/>
			<geom name="Glider_collision" class="unused" type="mesh" group="3" friction="1 0.0050000000000000001 0.0001" pos="0 0 0" euler="0 -0 0" mesh="Glider"/>
			<geom name="Glider_visual" class="unused" type="mesh" contype="0" conaffinity="0" group="0" pos="0 0 0" euler="0 -0 0" mesh="Glider"/>
			<joint name="Slider1" class="unused" type="slide" pos="1.8038723621230379e-05 -2.0931080508823641e-06 -0.12155235075527027" axis="-0.0001485178423013016 -5.6214670093840648e-08 0.99999998897122366" limited="true" range="-0.20000000000000001 0.39000000000000001"/>
			<body name="Ext_Holder" pos="-5.2592823887608921e-07 -0.0041450422041162671 0.02456458809208184" euler="0 -0 0">
				<inertial pos="0 0 0" mass="0.59422050168646334" fullinertia="0.00029118736875434481 0.00044525401105720448 0.00035855008037949577 -1.1925661837612901e-07 -2.3398724991885446e-08 1.7691439615600759e-05"/>
				<geom name="Ext_Holder_collision" class="unused" type="mesh" group="3" friction="1 0.0050000000000000001 0.0001" pos="0 0 0" euler="0 -0 0" mesh="Ext_Holder"/>
				<geom name="Ext_Holder_visual" class="unused" type="mesh" contype="0" conaffinity="0" group="0" pos="0 0 0" euler="0 -0 0" mesh="Ext_Holder"/>
				<joint name="Revolute3" class="unused" type="hinge" pos="-7.8427560669738772e-11 0.0041429420692316588 -0.021116940225950009" axis="-0.9999997024401851 -0.00075700858113645654 -0.00014851784230131182" limited="true" range="0 360"/>
			</body>
		</body>
	</body>
	</worldbody>
	<equality>
		<connect name="equality_constraint" active="true" body1="Ext_Cover" body2="Ext_Holder" anchor="0 0 0" />
	</equality>
</mujoco>